Workbook
Name cash.2009: '[1]Analyze Organization Financial '!$B$3
Name cash.2009: '[2]Analyze Organization Financial '!$B$3
Name depreciation.2009: '[1]Analyze Organization Financial '!$B$6
Name depreciation.2009: '[2]Analyze Organization Financial '!$B$6
Name expenses.2009: '[1]Analyze Organization Financial '!$B$7
Name expenses.2009: '[2]Analyze Organization Financial '!$B$7
Name FinanceRate: '[1]Capital Project'!$B$21
Name FinanceRate: '[2]Capital Project'!$B$21
Name LongTermInvestments.2009: '[1]Analyze Organization Financial '!$B$11
Name LongTermInvestments.2009: '[2]Analyze Organization Financial '!$B$11
Name NetIncome.2009: '[1]Analyze Organization Financial '!$B$9
Name NetIncome.2009: '[2]Analyze Organization Financial '!$B$9
Name Total.Assets.2009: '[1]Analyze Organization Financial '!$B$12
Name Total.Assets.2009: '[2]Analyze Organization Financial '!$B$12
Name Total.Revenue.2009: '[1]Analyze Organization Financial '!$B$16
Name Total.Revenue.2009: '[2]Analyze Organization Financial '!$B$16

Sheet Income Statement
A1: Jiranna Healthcare Income Statement December 31, 2021 (in thousands)
B3: 2017 | C3: 2018 | D3: 2019 | E3: 2020 | F3: 2021
A4: Gross patient services revenues (non-GAAP) | B4: 8870 | C4: 9490 | D4: 10400 | E4: 11200 | F4: 12050
A5: Less deductions from revenues (non-GAAP) | B5: -780 | C5: -890 | D5: -1000 | E5: -1500 | F5: -1600
A6: Net patient service revenues | B6: =SUM(B4:B5) -> 8090 | C6: =SUM(C4:C5) -> 8600 | D6: =SUM(D4:D5) -> 9400 | E6: =SUM(E4:E5) -> 9700 | F6: =SUM(F4:F5) -> 10450
A7: Other operating revenues | B7: 519 | C7: 633 | D7: 679 | E7: 717 | F7: 980
A8: Total operating revenues | B8: =SUM(B6:B7) -> 8609 | C8: =SUM(C6:C7) -> 9233 | D8: =SUM(D6:D7) -> 10079 | E8: =SUM(E6:E7) -> 10417 | F8: =SUM(F6:F7) -> 11430
A10: Operating expenses
A11: Salaries and wages | B11: 5497 | C11: 5678 | D11: 5890 | E11: 6170 | F11: 6800
A12: Supplies | B12: 823 | C12: 850 | D12: 855 | E12: 890 | F12: 905
A13: Utilities | B13: 558 | C13: 576 | D13: 590 | E13: 595 | F13: 620
A14: Insurance | B14: 44 | C14: 46 | D14: 49 | E14: 54 | F14: 70
A15: Depreciation | B15: 168 | C15: 173 | D15: 175 | E15: 178 | F15: 188
A16: Interest | B16: 142 | C16: 146 | D16: 154 | E16: 179 | F16: 198
A17: Bad debts | B17: 363 | C17: 375 | D17: 400 | E17: 455 | F17: 500
A18: Other operating expenses | B18: 987 | C18: 1299 | D18: 1560 | E18: 1300 | F18: 1350
A19: Total operating expenses | B19: =SUM(B11:B18) -> 8582 | C19: =SUM(C11:C18) -> 9143 | D19: =SUM(D11:D18) -> 9673 | E19: =SUM(E11:E18) -> 9821 | F19: =SUM(F11:F18) -> 10631
A21: Operating income | B21: =B8-B19 -> 27 | C21: =C8-C19 -> 90 | D21: =D8-D19 -> 406 | E21: =E8-E19 -> 596 | F21: =F8-F19 -> 799
A22: Nonoperating income | B22: 154 | C22: 195 | D22: 245 | E22: 220 | F22: 290
A23: Excess of revenue over expenses | B23: =B21+B22 -> 181 | C23: =C21+C22 -> 285 | D23: =D21+D22 -> 651 | E23: =E21+E22 -> 816 | F23: =F21+F22 -> 1089
A25: Change in net assets
A26: Unrestricted | B26: =B23 -> 181 | C26: =C23 -> 285 | D26: =D23 -> 651 | E26: =E23 -> 816 | F26: =F23 -> 1089
A27: Temporarily restricted | B27: 0 | C27: 0 | D27: 0 | E27: 0 | F27: 0
A28: Permanently restricted | B28: 0 | C28: 0 | D28: 0 | E28: 0 | F28: 0
A29: Total change in net assets | B29: =B26 -> 181 | C29: =C26 -> 285 | D29: =D26 -> 651 | E29: =E26 -> 816 | F29: =F26 -> 1089

Sheet Balance Sheet
A1: Jiranna Healthcare Balance Sheet December 31, 2021 (in thousands)
B3: 2017 | C3: 2018 | D3: 2019 | E3: 2020 | F3: 2021
A4: Current assets | B4: 280 | C4: 124 | D4: 136 | E4: 295 | F4: 355
A5: Cash | B5: 30 | C5: 45 | D5: 50 | E5: 75 | F5: 88
A6: Receivables, net | B6: 1340 | C6: 1536 | D6: 1700 | E6: 1896 | F6: 2400
A7: Inventory | B7: 140 | C7: 175 | D7: 250 | E7: 276 | F7: 266
A8: Prepaid expenses | B8: 40 | C8: 32 | D8: 40 | E8: 53 | F8: 78
A9: Total Current Assets | B9: =SUM(B4:B8) -> 1830 | C9: =SUM(C4:C8) -> 1912 | D9: =SUM(D4:D8) -> 2176 | E9: =SUM(E4:E8) -> 2595 | F9: =SUM(F4:F8) -> 3187
A11: Short-term investments | B11: 600 | C11: 1010 | D11: 1200 | E11: 1300 | F11: 1510
A12: Plant and equipment | B12: 6580 | C12: 6780 | D12: 6900 | E12: 7200 | F12: 7500
A13: Less accumulated depreciation | B13: -1660 | C13: -1750 | D13: -1800 | E13: -1950 | F13: -2350
A14: Plants and equipment, net | B14: =B12+B13 -> 4920 | C14: =C12+C13 -> 5030 | D14: =D12+D13 -> 5100 | E14: =E12+E13 -> 5250 | F14: =F12+F13 -> 5150
A15: Total Assets | B15: =SUM(B9+B11+B14) -> 7350 | C15: =SUM(C9+C11+C14) -> 7952 | D15: =SUM(D9+D11+D14) -> 8476 | E15: =SUM(E9+E11+E14) -> 9145 | F15: =SUM(F9+F11+F14) -> 9847
A17: Current liabilities
A18: Accounts payable | B18: 370 | C18: 302 | D18: 356 | E18: 370 | F18: 375
A19: Accrued expenses payable | B19: 220 | C19: 208 | D19: 212 | E19: 210 | F19: 215
A20: Deferred revenues | B20: 60 | C20: 77 | D20: 87 | E20: 87 | F20: 94
A21: Total current liabilities | B21: =SUM(B18:B20) -> 650 | C21: =SUM(C18:C20) -> 587 | D21: =SUM(D18:D20) -> 655 | E21: =SUM(E18:E20) -> 667 | F21: =SUM(F18:F20) -> 684
A22: Long-term liabilities | B22: 2400 | C22: 3000 | D22: 3300 | E22: 3500 | F22: 3750
A23: Total Liabilities | B23: =SUM(B21:B22) -> 3050 | C23: =SUM(C21:C22) -> 3587 | D23: =SUM(D21:D22) -> 3955 | E23: =SUM(E21:E22) -> 4167 | F23: =SUM(F21:F22) -> 4434
A25: Net assets
A26: Unrestricted | B26: 3000 | C26: 3285 | D26: 3221 | E26: 3678 | F26: 4113
A27: Temporarily restricted | B27: 700 | C27: 700 | D27: 700 | E27: 700 | F27: 700
A28: Permanently restricted | B28: 600 | C28: 600 | D28: 600 | E28: 600 | F28: 600
A29: Total Net Assets | B29: =SUM(B26:B28) -> 4300 | C29: =SUM(C26:C28) -> 4585 | D29: 4521 | E29: 4978 | F29: 5413
A30: Total Liabilities and Net Assets | B30: =SUM(B23+B29) -> 7350 | C30: =SUM(C29+C23) -> 8172 | D30: =SUM(D29+D23) -> 8476 | E30: =SUM(E29+E23) -> 9145 | F30: =SUM(F29+F23) -> 9847

Sheet Cash Flows
A1: Jiranna Healthcare Cash Flows, 2021 (in thousands)
A3: Cash Flows from Operating Activities
A4: Cash received from patient and third-party payers | B4: 10671
A5: Cash received from operating revenue sources | B5: 800
A6: Cash received from nonoperating revenue sources | B6: 270
A7: Cash payments to employees | B7: -5600
A8: Cash payments to suppliers of goods and services | B8: -4800
A9: Net cash flow from operating activities | C9: =SUM(B4:B8) -> 1341
A11: Cash flows from Investing Activities
A12: Cash payments for purchase of plant assets | B12: -1200
A13: Cash payments for purchase of long-term investments | B13: -670
A14: Proceeds from sales of plant assets | B14: 80
A15: Proceeds from sale of long-term investments | B15: 60
A16: Net cash flow from investing activities | C16: =SUM(B12:B15) -> -1730
A18: Cash flows from Financing Activities
A19: Proceeds from issuance of 6% bonds payable | B19: 4000
A20: Principal payments on long-term debt | B20: -300
A21: Cash payments to retire 7% bonds payable | B21: -3200
A22: Net cash flow from financing activities | C22: =SUM(B19:B21) -> 500
A23: Net increase/(decrease) in cash | C23: =SUM(C9:C22) -> 111

Sheet Part One
A2: Jiranna Financials | B2: 2017 | C2: 2018 | D2: 2019 | E2: 2020 | F2: 2021
A3: Total Net Sales | B3: ='Income Statement'!B8 -> 8609 | C3: ='Income Statement'!C8 -> 9233 | D3: ='Income Statement'!D8 -> 10079 | E3: ='Income Statement'!E8 -> 10417 | F3: ='Income Statement'!F8 -> 11430
A4: Operating Expenses | B4: 8582 | C4: 9143 | D4: 9673 | E4: 9821 | F4: 10631
A5: Operating Income | B5: 27 | C5: 90 | D5: 406 | E5: 596 | F5: 799
A6: Net Income | B6: 181 | C6: 285 | D6: 651 | E6: 816 | F6: 1089
A8: Profitability | B8: 2017 | C8: 2018 | D8: 2019 | E8: 2020 | F8: 2021
A9: Total Profit Margin | B9: =B6/B3 -> 0.021024509 | C9: =C6/C3 -> 0.03086754 | D9: =D6/D3 -> 0.064589741 | E9: =E6/E3 -> 0.078333493 | F9: =F6/F3 -> 0.095275591
A10: Total Assets | B10: 7350 | C10: 7952 | D10: 8476 | E10: 9145 | F10: 9847
A11: Asset Turnover | B11: =B3/B10 -> 1.1712925 | C11: =C3/C10 -> 1.1610915 | D11: =D3/D10 -> 1.1891222 | E11: =E3/E10 -> 1.1390924 | F11: =F3/F10 -> 1.1607596
A12: total net assets(balance sheet) | B12: 4300 | C12: 4585 | D12: 4521 | E12: 4978 | F12: 5413
A13: Return on Assets | B13: =B6/B10 -> 0.02462585 | C13: =C6/C10 -> 0.03584004 | D13: =D6/D10 -> 0.076805097 | E13: =E6/E10 -> 0.089229087 | F13: =F6/F10 -> 0.11059206
A14: Return on Net Worth | B14: =B6/B12 -> 0.042093023 | C14: =C6/C12 -> 0.062159215 | D14: =D6/D12 -> 0.14399469 | E14: =E6/E12 -> 0.16392125 | F14: =F6/F12 -> 0.20118234
A16: Liquidity Analysis | B16: 2017 | C16: 2018 | D16: 2019 | E16: 2020 | F16: 2021
A17: Total Current Assets(balance sheet) | B17: 1830 | C17: 1912 | D17: 2176 | E17: 2595 | F17: 3187
A18: Total current liabilities(balance sheet) | B18: 650 | C18: 587 | D18: 655 | E18: 667 | F18: 684
A19: Current Ratio | B19: =B17/B18 -> 2.8153846 | C19: =C17/C18 -> 3.2572402 | D19: =D17/D18 -> 3.3221374 | E19: =E17/E18 -> 3.8905547 | F19: =F17/F18 -> 4.6593567
A20: Days Cash on Hand | B20: 71.577133 | C20: 69.378484 | D20: 72.477364 | E20: 85.771026 | F20: 99.367519
A21: Working Capital | B21: =B17-B18 -> 1180 | C21: =C17-C18 -> 1325 | D21: =D17-D18 -> 1521 | E21: =E17-E18 -> 1928 | F21: =F17-F18 -> 2503
A23: Longterm Solvency | B23: 2017 | C23: 2018 | D23: 2019 | E23: 2020 | F23: 2021
A24: Total liabilities | B24: 3050 | C24: 3587 | D24: 3955 | E24: 4167 | F24: 4434
A25: Debt Ratio | B25: =B24/B10 -> 0.41496599 | C25: =C24/C10 -> 0.45108149 | D25: =D24/D10 -> 0.46661161 | E25: =E24/E10 -> 0.45565883 | F25: =F24/F10 -> 0.45028943
A26: Times Interest Earned | B26: 1.19 | C26: 1.62 | D26: 3.64 | E26: 4.33 | F26: 5.04
A28: DuPont | B28: 2017 | C28: 2018 | D28: 2019 | E28: 2020 | F28: 2021
A29: Net income(income statement) | B29: 181 | C29: 285 | D29: 651 | E29: 816 | F29: 1089
A30: Total revenue(income statement) | B30: 8609 | C30: 9233 | D30: 10079 | E30: 10417 | F30: 11430
A31: Net Profit Margin | B31: =B29/B30 -> 0.021024509 | C31: =C29/C30 -> 0.03086754 | D31: =D29/D30 -> 0.064589741 | E31: =E29/E30 -> 0.078333493 | F31: =F29/F30 -> 0.095275591
A32: Asset Turnover | B32: ='Income Statement'!B8/'Balance Sheet'!B15 -> 1.1712925 | C32: ='Income Statement'!C8/'Balance Sheet'!C15 -> 1.1610915 | D32: ='Income Statement'!D8/'Balance Sheet'!D15 -> 1.1891222 | E32: ='Income Statement'!E8/'Balance Sheet'!E15 -> 1.1390924 | F32: ='Income Statement'!F8/'Balance Sheet'!F15 -> 1.1607596
A33: Equity Multiplier | B33: ='Balance Sheet'!B15/'Balance Sheet'!B29 -> 1.7093023 | C33: ='Balance Sheet'!C15/'Balance Sheet'!C29 -> 1.7343511 | D33: ='Balance Sheet'!D15/'Balance Sheet'!D29 -> 1.8748065 | E33: ='Balance Sheet'!E15/'Balance Sheet'!E29 -> 1.8370832 | F33: ='Balance Sheet'!F15/'Balance Sheet'!F29 -> 1.8191391
A34: DuPont Analysis | B34: =B31*B32*B33 -> 0.042093023 | C34: =C31*C32*C33 -> 0.062159215 | D34: =D31*D32*D33 -> 0.14399469 | E34: =E31*E32*E33 -> 0.16392125 | F34: =F31*F32*F33 -> 0.20118234

Sheet Part one analysis
B1: 2017 | C1: 2018 | D1: 2019 | E1: 2020 | F1: 2021
A2: cash(balance sheet) | B2: ='Balance Sheet'!B9-('Balance Sheet'!B7+'Balance Sheet'!B8+'Balance Sheet'!B11) -> 1050 | C2: ='Balance Sheet'!C9-('Balance Sheet'!C7+'Balance Sheet'!C8+'Balance Sheet'!C11) -> 695 | D2: ='Balance Sheet'!D9-('Balance Sheet'!D7+'Balance Sheet'!D8+'Balance Sheet'!D11) -> 686 | E2: ='Balance Sheet'!E9-('Balance Sheet'!E7+'Balance Sheet'!E8+'Balance Sheet'!E11) -> 966 | F2: ='Balance Sheet'!F9-('Balance Sheet'!F7+'Balance Sheet'!F8+'Balance Sheet'!F11) -> 1333
A3: short term investments(balance sheet | B3: 600 | C3: 1010 | D3: 1200 | E3: 1300 | F3: 1510
A4: operating expenses(income statement) | B4: 8582 | C4: 9143 | D4: 9673 | E4: 9821 | F4: 10631
A5: depraciation(income statement) | B5: 168 | C5: 173 | D5: 175 | E5: 178 | F5: 188
A6: Numerator | B6: =B2+B3 -> 1650 | C6: =C2+C3 -> 1705 | D6: =D2+D3 -> 1886 | E6: =E2+E3 -> 2266 | F6: =F2+F3 -> 2843
A7: operating expense-depreciation | B7: =B4-B5 -> 8414 | C7: =C4-C5 -> 8970 | D7: =D4-D5 -> 9498 | E7: =E4-E5 -> 9643 | F7: =F4-F5 -> 10443
A8: days in a year | B8: 365 | C8: 365 | D8: 365 | E8: 365 | F8: 365
A9: Denominator | B9: =B7/B8 -> 23.052055 | C9: =C7/C8 -> 24.575342 | D9: =D7/D8 -> 26.021918 | E9: =E7/E8 -> 26.419178 | F9: =F7/F8 -> 28.610959
A10: days cash on hand | B10: =B6/B9 -> 71.577133 | C10: =C6/C9 -> 69.378484 | D10: =D6/D9 -> 72.477364 | E10: =E6/E9 -> 85.771026 | F10: =F6/F9 -> 99.367519
A11: operating income+expense | B11: ='Income Statement'!B21+'Income Statement'!B16 -> 169 | C11: ='Income Statement'!C21+'Income Statement'!C16 -> 236 | D11: ='Income Statement'!D21+'Income Statement'!D16 -> 560 | E11: ='Income Statement'!E21+'Income Statement'!E16 -> 775 | F11: ='Income Statement'!F21+'Income Statement'!F16 -> 997
A12: Interest expense | B12: 142 | C12: 146 | D12: 154 | E12: 179 | F12: 198
A13: Times Interest Earned | B13: =B11/B12 -> 1.1901408 | C13: =C11/C12 -> 1.6164384 | D13: =D11/D12 -> 3.6363636 | E13: =E11/E12 -> 4.3296089 | F13: =F11/F12 -> 5.0353535

Sheet Part Two
B1: Year 0 | C1: Year 1 | D1: Year 2 | E1: Year 3 | F1: Year 4 | G1: Year 5
A2: Nurse Triage Salaries | B2: 523800 | C2: 549990 | D2: 577490 | E2: 606364 | F2: 636682 | G2: 668516
A3: Forecasted ER Cost Reductions | B3: 400000 | C3: 800000 | D3: 848000 | E3: 900577 | F3: 955512 | G3: 1013798
A4: New IT Specialist's Salary | B4: 150000 | C4: 154500 | D4: 159135 | E4: 163909 | F4: 168826 | G4: 173891
A5: Costs of Facility Renovations | B5: 30000 | C5: 0 | D5: 0 | E5: 0 | F5: 0 | G5: 0
A6: Necessary Capital Equipment Purchases | B6: 117000 | C6: 3510 | D6: 3510 | E6: 3510 | F6: 3510 | G6: 3510
A7: Net Cash Flow: | B7: -420800 | C7: 92000 | D7: 107865 | E7: 126794 | F7: 146494 | G7: 167881
A8: Present Values of Net Cash Flows: | B8: -420800 | C8: 82882.883 | D8: 87545.654 | E8: 92710.68 | F8: 96500.135 | G8: 99629.202
A9: Net Present Value: | B9: 38468.554 | C9: PASS
A10: Internal Rate of Return (IRR): | B10: 0.14214618 | C10: PASS
A11: Modified Internal Rate of Return (MIRR): | B11: 0.12959087
A12: Payback Period (# years): | B12: 3.642627 | C12: FAIL
A13: Discounted Payback Period (# years): | B13: 4.6138827 | C13: FAIL
A18: Calculation for Discounted Payback Period
B19: Breakeven/Payback Period Years Based on PV of Net Cash Flows | C19: Disc cum cash flow | D19: Cum Cash Flow
B20: 0 | C20: -420800 | D20: -420800
A21: Net Cash Flow: | B21: 1 | C21: -337917 | D21: -328800
A22: PV cash flow | B22: 2 | C22: -250371 | D22: -220935
A23: Cumulative cash flow | B23: 3 | C23: -157661 | D23: -94141
B24: 4 | C24: -61160 | D24: 52353
B25: 5 | C25: 38468.55 | D25: 220234
B26: Discounted PayBack Period in Years | D26: 4.61

Sheet Part 2 analysis.
B1: YEARS
B2: 0 | C2: 1 | D2: 2 | E2: 3 | F2: 4 | G2: 5
A3: ='Part Two'!A3 -> Forecasted ER Cost Reductions | B3: ='Part Two'!B3 -> 400000 | C3: ='Part Two'!C3 -> 800000 | D3: ='Part Two'!D3 -> 848000 | E3: ='Part Two'!E3 -> 900577 | F3: ='Part Two'!F3 -> 955512 | G3: ='Part Two'!G3 -> 1013798
A4: ='Part Two'!A2 -> Nurse Triage Salaries | B4: ='Part Two'!B2 -> 523800 | C4: ='Part Two'!C2 -> 549990 | D4: ='Part Two'!D2 -> 577490 | E4: ='Part Two'!E2 -> 606364 | F4: ='Part Two'!F2 -> 636682 | G4: ='Part Two'!G2 -> 668516
A5: ='Part Two'!A4 -> New IT Specialist's Salary | B5: ='Part Two'!B4 -> 150000 | C5: ='Part Two'!C4 -> 154500 | D5: ='Part Two'!D4 -> 159135 | E5: ='Part Two'!E4 -> 163909 | F5: ='Part Two'!F4 -> 168826 | G5: ='Part Two'!G4 -> 173891
A6: ='Part Two'!A5 -> Costs of Facility Renovations | B6: ='Part Two'!B5 -> 30000 | C6: ='Part Two'!C5 -> 0 | D6: ='Part Two'!D5 -> 0 | E6: ='Part Two'!E5 -> 0 | F6: ='Part Two'!F5 -> 0 | G6: ='Part Two'!G5 -> 0
A7: ='Part Two'!A6 -> Necessary Capital Equipment Purchases | B7: ='Part Two'!B6 -> 117000 | C7: ='Part Two'!C6 -> 3510 | D7: ='Part Two'!D6 -> 3510 | E7: ='Part Two'!E6 -> 3510 | F7: ='Part Two'!F6 -> 3510 | G7: ='Part Two'!G6 -> 3510
A8: Total Outflows | B8: =SUM(B4:B7) -> 820800 | C8: =SUM(C4:C7) -> 708000 | D8: =SUM(D4:D7) -> 740135 | E8: =SUM(E4:E7) -> 773783 | F8: =SUM(F4:F7) -> 809018 | G8: =SUM(G4:G7) -> 845917
A9: Net Cashflows | B9: =B3-B8 -> -420800 | C9: =C3-C8 -> 92000 | D9: =D3-D8 -> 107865 | E9: =E3-E8 -> 126794 | F9: =F3-F8 -> 146494 | G9: =G3-G8 -> 167881
A10: Cumulative Cash Flow | B10: =B9 -> -420800 | C10: =B10+C9 -> -328800 | D10: =C10+D9 -> -220935 | E10: =D10+E9 -> -94141 | F10: =E10+F9 -> 52353 | G10: =F10+G9 -> 220234
A11: Payback Period | B11: =3+ABS(E10)/F9 -> 3.642627
A12: Net Present Value(NPV) | B12: =NPV(0.11,C9:G9)+B9 -> 38468.554
A13: Internal Rate of Return(IRR) | B13: =IRR(B9:G9) -> 0.14214618
A14: Modified Internal Rate of return(MIRR) | B14: =MIRR(B9:G9,0.11,0.11) -> 0.12959087
A15: Present value of net cash flow | B15: =B9/(1.11^B2) -> -420800 | C15: =C9/(1.11^C2) -> 82882.883 | D15: =D9/(1.11^D2) -> 87545.654 | E15: =E9/(1.11^E2) -> 92710.68 | F15: =F9/(1.11^F2) -> 96500.135 | G15: =G9/(1.11^G2) -> 99629.202
A16: Cumulative discounted cash flows | B16: =B15 -> -420800 | C16: =B16+C15 -> -337917.12 | D16: =C16+D15 -> -250371.46 | E16: =D16+E15 -> -157660.78 | F16: =E16+F15 -> -61160.648 | G16: =F16+G15 -> 38468.554
A17: Discounted Playback period | B17: =4+ABS(F16)/G15 -> 4.6138827

Sheet Variance Analysis Case Study
A2: Jiranna Healthcare Expenses Worksheet, Mid-Year Review
A3: Outpatient
A4: Outpatient Product Line | B4: Unit Expense (FY20) | C4: Actual Units (FY20) | D4: Total OP Expenses (FY20) | E4: Unit Forecast (FY21) | F4: Unit Expence (Budget FY21) | G4: FY21 Budget (FY20+6% Inflation) | H4: Acutal Mid Year Units (FY21) | I4: Actual OP Expenses (FY21 YTD)
A5: CARDIOLOGY | B5: =D5/C5 -> 5478.8093 | C5: 645 | D5: 3533832 | E5: 677 | F5: =G5/E5 -> 5807.5391 | G5: 3931704 | H5: 197 | I5: =F5*H5 -> 1144085.2
A6: ENDOCRINOLOYGY | B6: =D6/C6 -> 5478.8111 | C6: 217 | D6: 1188902 | E6: 228 | F6: =G6/E6 -> 5807.5395 | G6: 1324119 | H6: 112 | I6: =F6*H6 -> 650444.42
A7: FAMILY MED | B7: =D7/C7 -> 5476.81 | C7: 1105 | D7: 6051875 | E7: 1161 | F7: =G7/E7 -> 5802.9182 | G7: 6737188 | H7: 636 | I7: =F7*H7 -> 3690656
A8: GYN | B8: =D8/C8 -> 5478.8077 | C8: 208 | D8: 1139592 | E8: 219 | F8: =G8/E8 -> 5794.2785 | G8: 1268947 | H8: 116 | I8: =F8*H8 -> 672136.31
A9: ENT | B9: =D9/C9 -> 5475.8101 | C9: 690 | D9: 3778309 | E9: 724 | F9: =G9/E9 -> 5804.3591 | G9: 4202356 | H9: 421 | I9: =F9*H9 -> 2443635.2
A10: MENTAL HEALTH | B10: =D10/C10 -> 498.78011 | C10: 1287 | D10: 641930 | E10: 1351 | F10: =G10/E10 -> 528.70688 | G10: 714283 | H10: 736 | I10: =F10*H10 -> 389128.27
A11: NEWBORN | B11: =D11/C11 -> 5478.8095 | C11: 698 | D11: 3824209 | E11: 733 | F11: =G11/E11 -> 5807.5389 | G11: 4256926 | H11: 433 | I11: =F11*H11 -> 2514664.3
A12: OB | B12: =D12/C12 -> 5478.8098 | C12: 1430 | D12: 7834698 | E12: 1501 | F12: =G12/E12 -> 5807.5383 | G12: 8717115 | H12: 868 | I12: =F12*H12 -> 5040943.3
A13: ORTHO | B13: =D13/C13 -> 5478.8103 | C13: 601 | D13: 3292765 | E13: 631 | F13: =G13/E13 -> 5807.5388 | G13: 3664557 | H13: 274 | I13: =F13*H13 -> 1591265.6
A14: PEDIATRICS | B14: =D14/C14 -> 5477.8065 | C14: 124 | D14: 679248 | E14: 130 | F14: =G14/E14 -> 5806.4769 | G14: 754842 | H14: 72 | I14: =F14*H14 -> 418066.34
A15: PODIATRY | B15: =D15/C15 -> 5478.8102 | C15: 2050 | D15: 11231561 | E15: 2152 | F15: =G15/E15 -> 5807.5386 | G15: 12497823 | H15: 800 | I15: =F15*H15 -> 4646030.9
A16: Total Expenses | B16: =SUM(B5:B15) -> 55280.875 | C16: =SUM(C5:C15) -> 9055 | D16: =SUM(D5:D15) -> 43196921 | E16: =SUM(E5:E15) -> 9507 | F16: =SUM(F5:F15) -> 58581.973 | G16: =SUM(G5:G15) -> 48069860 | H16: =SUM(H5:H15) -> 4665 | I16: =SUM(I5:I15) -> 23201056
A18: Jiranna Healthcare Revenues Worksheet, Mid-Year Review
A19: Outpatient
A20: Outpatient Product Line | B20: Unit Price (FY20) | C20: Actual Units (FY20) | D20: Total OP Revenue (FY20) | E20: Unit Forecasted For (FY21) | F20: Unit Price (Budget FY21) | G20: Projected OP Revenue For FY21 | H20: Actual Units (FY21 YTD) | I20: Actual OP Revenue (FY21 YTD)
A21: CARDIOLOGY | B21: 6118.73 | C21: 645 | D21: =SUM(B21*C21) -> 3946580.8 | E21: 677 | F21: =G21/E21 -> 6118.7297 | G21: 4142380 | H21: 197 | I21: =F21*H21 -> 1205389.7
A22: ENDOCRINOLOYGY | B22: 6103.65 | C22: 217 | D22: =SUM(B22*C22) -> 1324492 | E22: 228 | F22: =G22/E22 -> 6103.6491 | G22: 1391632 | H22: 112 | I22: =F22*H22 -> 683608.7
A23: FAMILY MED | B23: 6021.65 | C23: 1105 | D23: =SUM(B23*C23) -> 6653923.2 | E23: 1161 | F23: =G23/E23 -> 6019.0568 | G23: 6988125 | H23: 636 | I23: =F23*H23 -> 3828120.2
A24: GYN | B24: 6013.65 | C24: 208 | D24: =SUM(B24*C24) -> 1250839.2 | E24: 219 | F24: =G24/E24 -> 5999.9224 | G24: 1313983 | H24: 116 | I24: =F24*H24 -> 695991
A25: ENT | B25: 6010.65 | C25: 690 | D25: =SUM(B25*C25) -> 4147348.5 | E25: 724 | F25: =G25/E25 -> 6010.6506 | G25: 4351711 | H25: 421 | I25: =F25*H25 -> 2530483.9
A26: MENTAL HEALTH | B26: 502.99 | C26: 1287 | D26: =SUM(B26*C26) -> 647348.13 | E26: 1351 | F26: =G26/E26 -> 502.98964 | G26: 679539 | H26: 736 | I26: =F26*H26 -> 370200.37
A27: NEWBORN | B27: 7014.71 | C27: 698 | D27: =SUM(B27*C27) -> 4896267.6 | E27: 733 | F27: =G27/E27 -> 7014.7094 | G27: 5141782 | H27: 433 | I27: =F27*H27 -> 3037369.2
A28: OB | B28: 5713.65 | C28: 1430 | D28: =SUM(B28*C28) -> 8170519.5 | E28: 1501 | F28: =G28/E28 -> 5713.6502 | G28: 8576189 | H28: 868 | I28: =F28*H28 -> 4959448.4
A29: ORTHO | B29: 6084.18 | C29: 601 | D29: =SUM(B29*C29) -> 3656592.2 | E29: 631 | F29: =G29/E29 -> 6084.1807 | G29: 3839118 | H29: 274 | I29: =F29*H29 -> 1667065.5
A30: PEDIATRICS | B30: 6001.65 | C30: 124 | D30: =SUM(B30*C30) -> 744204.6 | E30: 130 | F30: =G30/E30 -> 6001.6538 | G30: 780215 | H30: 72 | I30: =F30*H30 -> 432119.08
A31: PODIATRY | B31: 6018.14 | C31: 2050 | D31: =SUM(B31*C31) -> 12337187 | E31: 2152 | F31: =G31/E31 -> 6018.1399 | G31: 12951037 | H31: 800 | I31: =F31*H31 -> 4814511.9
A32: Total Revenue | B32: =SUM(B21:B31) -> 61603.65 | C32: =SUM(C21:C31) -> 9055 | D32: =SUM(D21:D31) -> 47775303 | E32: =SUM(E21:E31) -> 9507 | F32: =SUM(F21:F31) -> 61587.332 | G32: =SUM(G21:G31) -> 50155711 | H32: =SUM(H21:H31) -> 4665 | I32: =SUM(I21:I31) -> 24224308
A36: Product Line | B36: MDC DescrOPtion
A37: CARDIOLOGY | B37: Diseases and Disorders of the Circulatory System (Hypertension, Heart Disease, etc.)
A38: ENDOCRINOLOYGY | B38: Diseases and Disorders of the Endocrin System (Diabetes Type 1 & 2, Thyroid Disorders, etc)
A39: FAMILY MED | B39: Family Primary Care and Disease Preventative Services
A40: GYN | B40: Diseases and Disorders of Women's Reproductive Health
A41: ENT | B41: Diseases and Disorders of the Ear, Nose, Mouth, and Throat
A42: MENTAL HEALTH | B42: Mental Diseases and Disorders
A43: NEWBORN | B43: Newborns and Other Neonates with Conditions Originating in Perinatal Period
A44: OB | B44: Pregnancy, Childbirth, and the Puerperium
A45: ORTHO | B45: Diseases and Disorders of the Musculoskeletal System and Connective Tissue
...

Sheet Part Three
A1: Jiranna Healthcare
A2: Projected Profit
B3: Projected (FY21) | C3: Projected (mid-year) | D3: Actual (mid-year) | E3: Revised FY21 Projection
A4: Revenue | B4: 50155711 | C4: =B4/2 -> 25077856 | D4: 24224308 | E4: =D4*2 -> 48448616
A5: Expenses | B5: 48069860 | C5: =B5/2 -> 24034930 | D5: 23201056 | E5: =D5*2 -> 46402112
A6: Profit | B6: =B4-B5 -> 2085851 | C6: =B6/2 -> 1042925.5 | D6: =D4-D5 -> 1023252.1 | E6: =D6*2 -> 2046504.3
A9: Jiranna Healthcare
A10: FY21 YTD Expense Variances
B11: I | C11: II | D11: III | E11: IV
A12: Outpatient Product Line | B12: FY21 YTD Budget | C12: Actual OP Expenses (FY21 YTD) | D12: Expense Variance (II-I) | E12: Favorable / Unfavorable
A13: CARDIOLOGY | B13: ='Variance Analysis Case Study'!G5/2 -> 1965852 | C13: 1144085.2 | D13: =C13-B13 -> -821766.79 | E13: =IF(D13>0,"Unfavorable","Favorable") -> Favorable
A14: ENDOCRINOLOYGY | B14: ='Variance Analysis Case Study'!G6/2 -> 662059.5 | C14: 650444.42 | D14: =C14-B14 -> -11615.079 | E14: =IF(D14>0,"Unfavorable","Favorable") -> Favorable
A15: FAMILY MED | B15: ='Variance Analysis Case Study'!G7/2 -> 3368594 | C15: 3690656 | D15: =C15-B15 -> 322061.96 | E15: =IF(D15>0,"Unfavorable","Favorable") -> Unfavorable
A16: GYN | B16: ='Variance Analysis Case Study'!G8/2 -> 634473.5 | C16: 672136.31 | D16: =C16-B16 -> 37662.811 | E16: =IF(D16>0,"Unfavorable","Favorable") -> Unfavorable
A17: ENT | B17: ='Variance Analysis Case Study'!G9/2 -> 2101178 | C17: 2443635.2 | D17: =C17-B17 -> 342457.19 | E17: =IF(D17>0,"Unfavorable","Favorable") -> Unfavorable
A18: MENTAL HEALTH | B18: ='Variance Analysis Case Study'!G10/2 -> 357141.5 | C18: 389128.27 | D18: =C18-B18 -> 31986.766 | E18: =IF(D18>0,"Unfavorable","Favorable") -> Unfavorable
A19: NEWBORN | B19: ='Variance Analysis Case Study'!G11/2 -> 2128463 | C19: 2514664.3 | D19: =C19-B19 -> 386201.34 | E19: =IF(D19>0,"Unfavorable","Favorable") -> Unfavorable
A20: OB | B20: ='Variance Analysis Case Study'!G12/2 -> 4358557.5 | C20: 5040943.3 | D20: =C20-B20 -> 682385.75 | E20: =IF(D20>0,"Unfavorable","Favorable") -> Unfavorable
A21: ORTHO | B21: ='Variance Analysis Case Study'!G13/2 -> 1832278.5 | C21: 1591265.6 | D21: =C21-B21 -> -241012.86 | E21: =IF(D21>0,"Unfavorable","Favorable") -> Favorable
A22: PEDIATRICS | B22: ='Variance Analysis Case Study'!G14/2 -> 377421 | C22: 418066.34 | D22: =C22-B22 -> 40645.338 | E22: =IF(D22>0,"Unfavorable","Favorable") -> Unfavorable
A23: PODIATRY | B23: ='Variance Analysis Case Study'!G15/2 -> 6248911.5 | C23: 4646030.9 | D23: =C23-B23 -> -1602880.6 | E23: =IF(D23>0,"Unfavorable","Favorable") -> Favorable
A24: Total Outpatient Expenses | B24: =SUM(B13:B23) -> 24034930 | C24: =SUM(C13:C23) -> 23201056 | D24: =SUM(D13:D23) -> -833874.23 | E24: =IF(D24>0,"Unfavorable","Favorable") -> Favorable
A27: Jiranna Healthcare
A28: Revenue Variances
B29: I | C29: II | D29: III | E29: IV
A30: Outpatient Product Line | B30: FY21 YTD Budget | C30: Actual OP Revenue (FY21 YTD) | D30: Revenue Variance (II-I) | E30: Favorable / Unfavorable
A31: CARDIOLOGY | B31: ='Variance Analysis Case Study'!G21/2 -> 2071190 | C31: 1205389.7 | D31: =C31-B31 -> -865800.25 | E31: =IF(D31>0,"Favorable","Unfavorable") -> Unfavorable
A32: ENDOCRINOLOYGY | B32: ='Variance Analysis Case Study'!G22/2 -> 695816 | C32: 683608.7 | D32: =C32-B32 -> -12207.298 | E32: =IF(D32>0,"Favorable","Unfavorable") -> Unfavorable
A33: FAMILY MED | B33: ='Variance Analysis Case Study'!G23/2 -> 3494062.5 | C33: 3828120.2 | D33: =C33-B33 -> 334057.66 | E33: =IF(D33>0,"Favorable","Unfavorable") -> Favorable
A34: GYN | B34: ='Variance Analysis Case Study'!G24/2 -> 656991.5 | C34: 695991 | D34: =C34-B34 -> 38999.495 | E34: =IF(D34>0,"Favorable","Unfavorable") -> Favorable
A35: ENT | B35: ='Variance Analysis Case Study'!G25/2 -> 2175855.5 | C35: 2530483.9 | D35: =C35-B35 -> 354628.38 | E35: =IF(D35>0,"Favorable","Unfavorable") -> Favorable
A36: MENTAL HEALTH | B36: ='Variance Analysis Case Study'!G26/2 -> 339769.5 | C36: 370200.37 | D36: =C36-B36 -> 30430.873 | E36: =IF(D36>0,"Favorable","Unfavorable") -> Favorable
A37: NEWBORN | B37: ='Variance Analysis Case Study'!G27/2 -> 2570891 | C37: 3037369.2 | D37: =C37-B37 -> 466478.18 | E37: =IF(D37>0,"Favorable","Unfavorable") -> Favorable
A38: OB | B38: ='Variance Analysis Case Study'!G28/2 -> 4288094.5 | C38: 4959448.4 | D38: =C38-B38 -> 671353.9 | E38: =IF(D38>0,"Favorable","Unfavorable") -> Favorable
A39: ORTHO | B39: ='Variance Analysis Case Study'!G29/2 -> 1919559 | C39: 1667065.5 | D39: =C39-B39 -> -252493.5 | E39: =IF(D39>0,"Favorable","Unfavorable") -> Unfavorable
A40: PEDIATRICS | B40: ='Variance Analysis Case Study'!G30/2 -> 390107.5 | C40: 432119.08 | D40: =C40-B40 -> 42011.577 | E40: =IF(D40>0,"Favorable","Unfavorable") -> Favorable
A41: PODIATRY | B41: ='Variance Analysis Case Study'!G31/2 -> 6475518.5 | C41: 4814511.9 | D41: =C41-B41 -> -1661006.6 | E41: =IF(D41>0,"Favorable","Unfavorable") -> Unfavorable
A42: Total Outpatient Revenues | B42: =SUM(B31:B41) -> 25077856 | C42: =SUM(C31:C41) -> 24224308 | D42: =SUM(D31:D41) -> -853547.59 | E42: =IF(D42>0,"Favorable","Unfavorable") -> Unfavorable
A45: Jiranna Healthcare
A46: Profit Variances
...
