Workbook

Sheet COMBINED ATTENDANCE TABLE
A1: SNo | B1: Participant Name | C1: AttendanceStartedat | D1: Joinedat(beta) | E1: Attendance Stoppedat | F1: Attended Duration | G1: Meeting code | H1: DAYS | I1: DURATION | J1: START SESSIONS | K1: END SESSIONS
A2: 1 | B2: AMARA BAJAHA | C2: 0.85984954 | D2: 0.93263889 | E2: 0.95210648 | F2: 15 min 11s | G2: qko-gvfr-grx | H2: 36 | I2: 0.092256944 | J2: =IF(AND(H2>=1,H2<=7),1,0) -> 0 | K2: =IF(AND(H2>=30,H2<=36),1,0) -> 1
A3: 2 | B3: ANGULA ROSAMUNDE | C3: 0.85984954 | D3: 0.85988426 | E3: 0.95210648 | F3: 2 hr 12 min 45s | G3: qko-gvfr-grx | H3: 36 | I3: 0.092256944 | J3: =IF(AND(H3>=1,H3<=7),1,0) -> 0 | K3: =IF(AND(H3>=30,H3<=36),1,0) -> 1
A4: 3 | B4: ANTHONY GODSON AIDOO | C4: 0.85984954 | D4: 0.85988426 | E4: 0.95210648 | F4: 2 hr 12 min 40s | G4: qko-gvfr-grx | H4: 36 | I4: 0.092256944 | J4: =IF(AND(H4>=1,H4<=7),1,0) -> 0 | K4: =IF(AND(H4>=30,H4<=36),1,0) -> 1
A5: 4 | B5: AZEDRIS JAMIL KASANGO | C5: 0.85984954 | D5: 0.93263889 | E5: 0.95210648 | F5: 28 min 3s | G5: qko-gvfr-grx | H5: 36 | I5: 0.092256944 | J5: =IF(AND(H5>=1,H5<=7),1,0) -> 0 | K5: =IF(AND(H5>=30,H5<=36),1,0) -> 1
A6: 6 | B6: GODFREY BIRUNGI | C6: 0.85984954 | D6: 0.85988426 | E6: 0.95210648 | F6: 2 hr 12 min 46s | G6: qko-gvfr-grx | H6: 36 | I6: 0.092256944 | J6: =IF(AND(H6>=1,H6<=7),1,0) -> 0 | K6: =IF(AND(H6>=30,H6<=36),1,0) -> 1
A7: 7 | B7: JOHN RWARU | C7: 0.85984954 | D7: 0.85988426 | E7: 0.95210648 | F7: 1 hr 44 min 43s | G7: qko-gvfr-grx | H7: 36 | I7: 0.092256944 | J7: =IF(AND(H7>=1,H7<=7),1,0) -> 0 | K7: =IF(AND(H7>=30,H7<=36),1,0) -> 1
A8: 8 | B8: KAMAU RUTH | C8: 0.85984954 | D8: 0.85988426 | E8: 0.95210648 | F8: 2 hr 12 min 39s | G8: qko-gvfr-grx | H8: 36 | I8: 0.092256944 | J8: =IF(AND(H8>=1,H8<=7),1,0) -> 0 | K8: =IF(AND(H8>=30,H8<=36),1,0) -> 1
A9: 9 | B9: MARTIN LEMI | C9: 0.85984954 | D9: 0.85988426 | E9: 0.95210648 | F9: 2 hr 12 min 46s | G9: qko-gvfr-grx | H9: 36 | I9: 0.092256944 | J9: =IF(AND(H9>=1,H9<=7),1,0) -> 0 | K9: =IF(AND(H9>=30,H9<=36),1,0) -> 1
A10: 10 | B10: MOHAMED SALLY KAMARA | C10: 0.85984954 | D10: 0.85988426 | E10: 0.95210648 | F10: 1 hr 58 min 27s | G10: qko-gvfr-grx | H10: 36 | I10: 0.092256944 | J10: =IF(AND(H10>=1,H10<=7),1,0) -> 0 | K10: =IF(AND(H10>=30,H10<=36),1,0) -> 1
A11: 11 | B11: OCI GEOFFREY | C11: 0.85984954 | D11: 0.93263889 | E11: 0.95210648 | F11: 25 min 23s | G11: qko-gvfr-grx | H11: 36 | I11: 0.092256944 | J11: =IF(AND(H11>=1,H11<=7),1,0) -> 0 | K11: =IF(AND(H11>=30,H11<=36),1,0) -> 1
A12: 12 | B12: YANGA SAMSON | C12: 0.85984954 | D12: 0.93263889 | E12: 0.95210648 | F12: 27 min 51s | G12: qko-gvfr-grx | H12: 36 | I12: 0.092256944 | J12: =IF(AND(H12>=1,H12<=7),1,0) -> 0 | K12: =IF(AND(H12>=30,H12<=36),1,0) -> 1
A13: 1 | B13: ALEX MUHEREZA | C13: 0.86208333 | D13: 0.86211806 | E13: 0.96212963 | F13: 2 hr 14 min 23s | G13: bvm-hrrr-qjc | H13: 35 | I13: 0.1000463 | J13: =IF(AND(H13>=1,H13<=7),1,0) -> 0 | K13: =IF(AND(H13>=30,H13<=36),1,0) -> 1
... A1364: 60 | B1364: YUSUPHA SEESAY | C1364: 0.85383102 | D1364: 0.85386574 | E1364: 0.93270833 | F1364: 1 hr 52 min 3s | G1364: dua-unee-xss | H1364: 1 | I1364: 0.078877315 | J1364: =IF(AND(H1364>=1,H1364<=7),1,0) -> 1 | K1364: =IF(AND(H1364>=30,H1364<=36),1,0) -> 0
I1367: =SUM(I2:I1364) -> 116.57457

Sheet SECTION B.
A1: PARTICIPANTS NAME | B1: COUNT(DAYS ATTENDED) | C1: TARGET SESSIONS(DAYS) | D1: ATTENDANCE(%)DAYS | E1: COUNT(DURATION) | F1: RANK
A2: GODFREY BIRUNGI | B2: 36 | C2: 36 | D2: =B2/C2 -> 1 | E2: 3.0720949 | F2: =_xlfn.RANK.EQ(D2,D:D,) -> 1
A3: ANTHONY GODSON AIDOO | B3: 35 | C3: 36 | D3: =B3/C3 -> 0.97222222 | E3: 2.9238773 | F3: =_xlfn.RANK.EQ(D3,D:D,) -> 2
A4: MARTIN LEMI | B4: 35 | C4: 36 | D4: =B4/C4 -> 0.97222222 | E4: 3.0000463 | F4: =_xlfn.RANK.EQ(D4,D:D,) -> 2
A5: RTN JOSES KAYUNGA | B5: 34 | C5: 36 | D5: =B5/C5 -> 0.94444444 | E5: 2.9219097 | F5: =_xlfn.RANK.EQ(D5,D:D,) -> 4
A6: JOHN RWARU | B6: 33 | C6: 36 | D6: =B6/C6 -> 0.91666667 | E6: 2.8203588 | F6: =_xlfn.RANK.EQ(D6,D:D,) -> 5
A7: KAMAU RUTH | B7: 33 | C7: 36 | D7: =B7/C7 -> 0.91666667 | E7: 2.7831597 | F7: =_xlfn.RANK.EQ(D7,D:D,) -> 5
A8: MILDRED DRUSILA | B8: 33 | C8: 36 | D8: =B8/C8 -> 0.91666667 | E8: 2.7944213 | F8: =_xlfn.RANK.EQ(D8,D:D,) -> 5
A9: JOSEPH MBOGO | B9: 31 | C9: 36 | D9: =B9/C9 -> 0.86111111 | E9: 2.6125579 | F9: =_xlfn.RANK.EQ(D9,D:D,) -> 8
A10: EMMANUEL JOBS | B10: 30 | C10: 36 | D10: =B10/C10 -> 0.83333333 | E10: 2.566088 | F10: =_xlfn.RANK.EQ(D10,D:D,) -> 9
A11: OMELLA OWEN | B11: 30 | C11: 36 | D11: =B11/C11 -> 0.83333333 | E11: 2.5218981 | F11: =_xlfn.RANK.EQ(D11,D:D,) -> 9
A12: BENJAMIN MALES LOKOYA | B12: 29 | C12: 36 | D12: =B12/C12 -> 0.80555556 | E12: 2.4394676 | F12: =_xlfn.RANK.EQ(D12,D:D,) -> 11
A13: CHRISTINA MOTHOBI | B13: 29 | C13: 36 | D13: =B13/C13 -> 0.80555556 | E13: 2.4302315 | F13: =_xlfn.RANK.EQ(D13,D:D,) -> 11
... A107: TIMOTENGINEERING LIMITED | B107: 1 | C107: 36 | D107: =B107/C107 -> 0.027777778 | E107: 0.083715278 | F107: =_xlfn.RANK.EQ(D107,D:D,) -> 92
B111: PERFORMANCE
B112: HIGH PERFORMANCE | C112: 15
B113: MODERATE PERFORMANCE | C113: 17
B114: AT-RISK PERFORMANCE | C114: 75

Sheet UNIQUE VALUES(NO DUPLICATES)
A1: Participant Name
A2: AMARA BAJAHA | B2: =ROWS(A2:A107) -> 106
A3: ANGULA ROSAMUNDE
A4: ANTHONY GODSON AIDOO
A5: AZEDRIS JAMIL KASANGO
A6: GODFREY BIRUNGI
A7: JOHN RWARU
A8: KAMAU RUTH
A9: MARTIN LEMI
A10: MOHAMED SALLY KAMARA
A11: OCI GEOFFREY
A12: YANGA SAMSON
A13: ALEX MUHEREZA
A14: BENJAMIN MALES LOKOYA
... A107: RAMATA M KEITA

Sheet PERFOEMANCE TABLE
A1: PARTICIPANTS NAME | B1: COUNT OF DAYS | C1: PLANNED DAYS | D1: PERCENTAGE DAYS ATTENDED | E1: SUM OF DURATION | F1: SUM OF DURAION | G1: PLANNED DURATION | H1: % HOURS | I1: % STANDARD HOURS | J1: COMBINED PERCENTAGE | K1: RANK | L1: PERFORMANCE RATES | M1: HIGH PERFORMERS | N1: MODERATE | O1: AT RISK | P1: 80% 0F SESSION ATTENDANCE
A2: GODFREY BIRUNGI | B2: 36 | C2: 36 | D2: =B2/C2 -> 1 | E2: 3.0720949 | F2: =E2*24 -> 73.730278 | G2: 72 | H2: =F2/G2 -> 1.0240316 | I2: =MIN(100%,H2) -> 1 | J2: =(D2*0.5)+(I2*0.5) -> 1 | K2: =RANK(J2,J:J,) -> 1 | L2: =IF(J2>=75%,"HIGH PERFORMERS",IF(J2>=50%,"MODERATE PERFORMERS","AT-RISK PERFORMERS")) -> HIGH PERFORMERS | M2: =COUNTA(L2:L17) -> 16 | N2: =COUNTA(L18:L32) -> 15 | O2: =COUNTA(L33:L106) -> 74 | P2: =COUNT(J2:J16) -> 15
A3: MARTIN LEMI | B3: 35 | C3: 36 | D3: =B3/C3 -> 0.97222222 | E3: 3.0000463 | F3: =E3*24 -> 72.001111 | G3: 72 | H3: =F3/G3 -> 1.0000154 | I3: =MIN(100%,H3) -> 1 | J3: =(D3*0.5)+(I3*0.5) -> 0.98611111 | K3: =RANK(J3,J:J,) -> 2 | L3: =IF(J3>=75%,"HIGH PERFORMERS",IF(J3>=50%,"MODERATE PERFORMERS","AT-RISK PERFORMERS")) -> HIGH PERFORMERS
A4: ANTHONY GODSON AIDOO | B4: 35 | C4: 36 | D4: =B4/C4 -> 0.97222222 | E4: 2.9238773 | F4: =E4*24 -> 70.173056 | G4: 72 | H4: =F4/G4 -> 0.97462577 | I4: =MIN(100%,H4) -> 0.97462577 | J4: =(D4*0.5)+(I4*0.5) -> 0.973424 | K4: =RANK(J4,J:J,) -> 3 | L4: =IF(J4>=75%,"HIGH PERFORMERS",IF(J4>=50%,"MODERATE PERFORMERS","AT-RISK PERFORMERS")) -> HIGH PERFORMERS
A5: RTN JOSES KAYUNGA | B5: 34 | C5: 36 | D5: =B5/C5 -> 0.94444444 | E5: 2.9219097 | F5: =E5*24 -> 70.125833 | G5: 72 | H5: =F5/G5 -> 0.97396991 | I5: =MIN(100%,H5) -> 0.97396991 | J5: =(D5*0.5)+(I5*0.5) -> 0.95920718 | K5: =RANK(J5,J:J,) -> 4 | L5: =IF(J5>=75%,"HIGH PERFORMERS",IF(J5>=50%,"MODERATE PERFORMERS","AT-RISK PERFORMERS")) -> HIGH PERFORMERS
A6: JOHN RWARU | B6: 33 | C6: 36 | D6: =B6/C6 -> 0.91666667 | E6: 2.8203588 | F6: =E6*24 -> 67.688611 | G6: 72 | H6: =F6/G6 -> 0.9401196 | I6: =MIN(100%,H6) -> 0.9401196 | J6: =(D6*0.5)+(I6*0.5) -> 0.92839313 | K6: =RANK(J6,J:J,) -> 5 | L6: =IF(J6>=75%,"HIGH PERFORMERS",IF(J6>=50%,"MODERATE PERFORMERS","AT-RISK PERFORMERS")) -> HIGH PERFORMERS
A7: MILDRED DRUSILA | B7: 33 | C7: 36 | D7: =B7/C7 -> 0.91666667 | E7: 2.7944213 | F7: =E7*24 -> 67.066111 | G7: 72 | H7: =F7/G7 -> 0.93147377 | I7: =MIN(100%,H7) -> 0.93147377 | J7: =(D7*0.5)+(I7*0.5) -> 0.92407022 | K7: =RANK(J7,J:J,) -> 6 | L7: =IF(J7>=75%,"HIGH PERFORMERS",IF(J7>=50%,"MODERATE PERFORMERS","AT-RISK PERFORMERS")) -> HIGH PERFORMERS
A8: KAMAU RUTH | B8: 33 | C8: 36 | D8: =B8/C8 -> 0.91666667 | E8: 2.7831597 | F8: =E8*24 -> 66.795833 | G8: 72 | H8: =F8/G8 -> 0.92771991 | I8: =MIN(100%,H8) -> 0.92771991 | J8: =(D8*0.5)+(I8*0.5) -> 0.92219329 | K8: =RANK(J8,J:J,) -> 7 | L8: =IF(J8>=75%,"HIGH PERFORMERS",IF(J8>=50%,"MODERATE PERFORMERS","AT-RISK PERFORMERS")) -> HIGH PERFORMERS
A9: JOSEPH MBOGO | B9: 31 | C9: 36 | D9: =B9/C9 -> 0.86111111 | E9: 2.6125579 | F9: =E9*24 -> 62.701389 | G9: 72 | H9: =F9/G9 -> 0.87085262 | I9: =MIN(100%,H9) -> 0.87085262 | J9: =(D9*0.5)+(I9*0.5) -> 0.86598187 | K9: =RANK(J9,J:J,) -> 8 | L9: =IF(J9>=75%,"HIGH PERFORMERS",IF(J9>=50%,"MODERATE PERFORMERS","AT-RISK PERFORMERS")) -> HIGH PERFORMERS
A10: EMMANUEL JOBS | B10: 30 | C10: 36 | D10: =B10/C10 -> 0.83333333 | E10: 2.566088 | F10: =E10*24 -> 61.586111 | G10: 72 | H10: =F10/G10 -> 0.85536265 | I10: =MIN(100%,H10) -> 0.85536265 | J10: =(D10*0.5)+(I10*0.5) -> 0.84434799 | K10: =RANK(J10,J:J,) -> 9 | L10: =IF(J10>=75%,"HIGH PERFORMERS",IF(J10>=50%,"MODERATE PERFORMERS","AT-RISK PERFORMERS")) -> HIGH PERFORMERS
A11: AMARA BAJAHA | B11: 25 | C11: 36 | D11: =B11/C11 -> 0.69444444 | E11: 2.9404051 | F11: =E11*24 -> 70.569722 | G11: 72 | H11: =F11/G11 -> 0.98013503 | I11: =MIN(100%,H11) -> 0.98013503 | J11: =(D11*0.5)+(I11*0.5) -> 0.83728974 | K11: =RANK(J11,J:J,) -> 10 | L11: =IF(J11>=75%,"HIGH PERFORMERS",IF(J11>=50%,"MODERATE PERFORMERS","AT-RISK PERFORMERS")) -> HIGH PERFORMERS
A12: OMELLA OWEN | B12: 30 | C12: 36 | D12: =B12/C12 -> 0.83333333 | E12: 2.5218981 | F12: =E12*24 -> 60.525556 | G12: 72 | H12: =F12/G12 -> 0.84063272 | I12: =MIN(100%,H12) -> 0.84063272 | J12: =(D12*0.5)+(I12*0.5) -> 0.83698302 | K12: =RANK(J12,J:J,) -> 11 | L12: =IF(J12>=75%,"HIGH PERFORMERS",IF(J12>=50%,"MODERATE PERFORMERS","AT-RISK PERFORMERS")) -> HIGH PERFORMERS
A13: MOHAMED SALLY KAMARA | B13: 29 | C13: 36 | D13: =B13/C13 -> 0.80555556 | E13: 2.4989005 | F13: =E13*24 -> 59.973611 | G13: 72 | H13: =F13/G13 -> 0.83296682 | I13: =MIN(100%,H13) -> 0.83296682 | J13: =(D13*0.5)+(I13*0.5) -> 0.81926119 | K13: =RANK(J13,J:J,) -> 12 | L13: =IF(J13>=75%,"HIGH PERFORMERS",IF(J13>=50%,"MODERATE PERFORMERS","AT-RISK PERFORMERS")) -> HIGH PERFORMERS
A14: BENJAMIN MALES LOKOYA | B14: 29 | C14: 36 | D14: =B14/C14 -> 0.80555556 | E14: 2.4394676 | F14: =E14*24 -> 58.547222 | G14: 72 | H14: =F14/G14 -> 0.81315586 | I14: =MIN(100%,H14) -> 0.81315586 | J14: =(D14*0.5)+(I14*0.5) -> 0.80935571 | K14: =RANK(J14,J:J,) -> 13 | L14: =IF(J14>=75%,"HIGH PERFORMERS",IF(J14>=50%,"MODERATE PERFORMERS","AT-RISK PERFORMERS")) -> HIGH PERFORMERS
... A106: KORIR | B106: 1 | C106: 36 | D106: =B106/C106 -> 0.027777778 | E106: 0.065439815 | F106: =E106*24 -> 1.5705556 | G106: 72 | H106: =F106/G106 -> 0.021813272 | I106: =MIN(100%,H106) -> 0.021813272 | J106: =(D106*0.5)+(I106*0.5) -> 0.024795525 | K106: =RANK(J106,J:J,) -> 105 | L106: =IF(J106>=75%,"HIGH PERFORMERS",IF(J106>=50%,"MODERATE PERFORMERS","AT-RISK PERFORMERS")) -> AT-RISK PERFORMERS
A114: PARTICIPANTS NAME | B114: PERCENTAGE DAYS ATTENDED | C114: % STANDARD HOURS | D114: COMBINED PERCENTAGE | E114: RANK
A115: GODFREY BIRUNGI | B115: 1 | C115: 1 | D115: 1 | E115: 1
A116: MARTIN LEMI | B116: 0.97222222 | C116: 1 | D116: 0.98611111 | E116: 2
A117: ANTHONY GODSON AIDOO | B117: 0.97222222 | C117: 0.97462577 | D117: 0.973424 | E117: 3
A118: RTN JOSES KAYUNGA | B118: 0.94444444 | C118: 0.97396991 | D118: 0.95920718 | E118: 4
A119: JOHN RWARU | B119: 0.91666667 | C119: 0.9401196 | D119: 0.92839313 | E119: 5
A120: MILDRED DRUSILA | B120: 0.91666667 | C120: 0.93147377 | D120: 0.92407022 | E120: 6
A121: KAMAU RUTH | B121: 0.91666667 | C121: 0.92771991 | D121: 0.92219329 | E121: 7
A122: JOSEPH MBOGO | B122: 0.86111111 | C122: 0.87085262 | D122: 0.86598187 | E122: 8
A123: EMMANUEL JOBS | B123: 0.83333333 | C123: 0.85536265 | D123: 0.84434799 | E123: 9
A124: AMARA BAJAHA | B124: 0.69444444 | C124: 0.98013503 | D124: 0.83728974 | E124: 10

Sheet PIVOT TABLES
A1: Count of DURATION | B1: Column Labels
A2: Row Labels | B2: Day_1 | C2: Day_10 | D2: Day_11 | E2: Day_12 | F2: Day_13 | G2: Day_14 | H2: Day_15 | I2: Day_16 | J2: Day_17 | K2: Day_18 | L2: Day_19 | M2: Day_2 | N2: Day_20 | O2: Day_21 | P2: Day_22 | Q2: Day_23 | R2: Day_24 | S2: Day_25 | T2: Day_26 | U2: Day_27 | V2: Day_28 | W2: Day_29 | X2: Day_3 | Y2: Day_30 | Z2: Day_31 | AA2: Day_34 | AB2: Day_35 | AC2: Day_36 | AD2: Day_37 | AE2: Day_38 | AF2: Day_4 | AG2: Day_5 | AH2: Day_6 | AI2: Day_7 | AJ2: Day_8 | AK2: Day_9 | AL2: Grand Total
A3: ALEX MUHEREZA | B3: 1 | C3: 1 | E3: 1 | G3: 1 | I3: 1 | J3: 1 | K3: 1 | P3: 1 | Q3: 1 | U3: 1 | Y3: 1 | AD3: 1 | AI3: 1 | AL3: 13
A4: AMARA BAJAHA | B4: 1 | D4: 1 | E4: 1 | F4: 1 | G4: 1 | H4: 1 | I4: 1 | J4: 1 | K4: 1 | L4: 1 | N4: 1 | O4: 1 | P4: 1 | Q4: 1 | R4: 1 | S4: 1 | U4: 1 | V4: 1 | W4: 1 | Z4: 1 | AA4: 1 | AB4: 1 | AC4: 1 | AD4: 1 | AE4: 1 | AL4: 25
A5: ANGULA ROSAMUNDE | C5: 1 | D5: 1 | E5: 1 | F5: 1 | G5: 1 | I5: 1 | J5: 1 | K5: 1 | M5: 1 | N5: 1 | O5: 1 | P5: 1 | Q5: 1 | R5: 1 | T5: 1 | U5: 1 | V5: 1 | W5: 1 | X5: 1 | Z5: 1 | AA5: 1 | AB5: 1 | AD5: 1 | AE5: 1 | AF5: 1 | AJ5: 1 | AK5: 1 | AL5: 27
A6: ANTHONY GODSON AIDOO | B6: 1 | C6: 1 | D6: 1 | E6: 1 | F6: 1 | G6: 1 | H6: 1 | I6: 1 | J6: 1 | K6: 1 | L6: 1 | M6: 1 | N6: 1 | O6: 1 | P6: 1 | Q6: 1 | R6: 1 | S6: 1 | T6: 1 | U6: 1 | V6: 1 | W6: 1 | X6: 1 | Y6: 1 | Z6: 1 | AA6: 1 | AB6: 1 | AC6: 1 | AD6: 1 | AE6: 1 | AF6: 1 | AH6: 1 | AI6: 1 | AJ6: 1 | AK6: 1 | AL6: 35
A7: ARON NTULIZE | B7: 1 | C7: 1 | D7: 1 | E7: 1 | H7: 1 | I7: 1 | J7: 1 | M7: 1 | O7: 1 | X7: 1 | AF7: 1 | AG7: 1 | AH7: 1 | AK7: 1 | AL7: 14
A8: AZEDRIS JAMIL KASANGO | R8: 1 | W8: 1 | Z8: 1 | AB8: 1 | AD8: 1 | AE8: 1 | AI8: 1 | AL8: 7
A9: BENJAMIN MALES LOKOYA | B9: 1 | C9: 1 | D9: 1 | E9: 1 | F9: 1 | G9: 1 | H9: 1 | I9: 1 | J9: 1 | K9: 1 | L9: 1 | M9: 1 | O9: 1 | P9: 1 | Q9: 1 | R9: 1 | S9: 1 | T9: 1 | U9: 1 | X9: 1 | AA9: 1 | AB9: 1 | AC9: 1 | AD9: 1 | AF9: 1 | AH9: 1 | AI9: 1 | AJ9: 1 | AK9: 1 | AL9: 29
A10: BIRUNGI'S AI NOTETAKER | M10: 1 | X10: 1 | AF10: 1 | AG10: 1 | AL10: 4
A11: CHANDIA FRED | X11: 1 | AG11: 1 | AH11: 1 | AI11: 1 | AK11: 1 | AL11: 5
A12: CHERUIYOT JULIUS | K12: 1 | AL12: 1
A13: CHERUU JUL | B13: 1 | D13: 1 | F13: 1 | I13: 1 | L13: 1 | M13: 1 | N13: 1 | P13: 1 | Q13: 1 | V13: 1 | W13: 1 | X13: 1 | Z13: 1 | AA13: 1 | AB13: 1 | AD13: 1 | AE13: 1 | AF13: 1 | AH13: 1 | AI13: 1 | AJ13: 1 | AK13: 1 | AL13: 22
A14: CHRISTINA MOTHOBI | B14: 1 | C14: 1 | D14: 1 | E14: 1 | F14: 1 | G14: 1 | H14: 1 | I14: 1 | J14: 1 | K14: 1 | L14: 1 | M14: 1 | N14: 1 | O14: 1 | P14: 1 | Q14: 1 | R14: 1 | S14: 1 | T14: 1 | V14: 1 | W14: 1 | X14: 1 | Y14: 1 | Z14: 1 | AA14: 1 | AB14: 1 | AF14: 1 | AH14: 1 | AK14: 1 | AL14: 29
A15: CHRISTOPHER MARK MODI | J15: 1 | AL15: 1
A16: CHRISTOPHER MODI | B16: 1 | D16: 1 | E16: 1 | F16: 1 | G16: 1 | H16: 1 | I16: 1 | K16: 1 | L16: 1 | M16: 1 | N16: 1 | P16: 1 | Q16: 1 | V16: 1 | X16: 1 | Y16: 1 | Z16: 1 | AC16: 1 | AF16: 1 | AG16: 1 | AI16: 1 | AJ16: 1 | AL16: 22
A17: CPAJULIUS CHERUIYOT | E17: 1 | G17: 1 | H17: 1 | L17: 1 | N17: 1 | O17: 1 | P17: 1 | Q17: 1 | S17: 1 | T17: 1 | U17: 1 | Y17: 1 | Z17: 1 | AA17: 1 | AL17: 14
A18: DANIEL ERABU | B18: 1 | H18: 1 | I18: 1 | J18: 1 | K18: 1 | X18: 1 | AF18: 1 | AG18: 1 | AH18: 1 | AI18: 1 | AJ18: 1 | AK18: 1 | AL18: 12
A19: DEUS NABIBASA | G19: 1 | I19: 1 | AL19: 2
A20: DIMA JAMES | Q20: 1 | R20: 1 | S20: 1 | Z20: 1 | AL20: 4
A21: EL MAJID SWALEH | B21: 1 | C21: 1 | D21: 1 | E21: 1 | F21: 1 | H21: 1 | I21: 1 | J21: 1 | K21: 1 | L21: 1 | M21: 1 | N21: 1 | O21: 1 | P21: 1 | Q21: 1 | R21: 1 | S21: 1 | T21: 1 | W21: 1 | X21: 1 | AG21: 1 | AH21: 1 | AI21: 1 | AJ21: 1 | AK21: 1 | AL21: 25
A22: EL-MAJID SWALEH | C22: 1 | G22: 1 | L22: 1 | AF22: 1 | AK22: 1 | AL22: 5
A23: EMMANUEL JOBS | B23: 1 | C23: 1 | D23: 1 | E23: 1 | F23: 1 | G23: 1 | H23: 1 | I23: 1 | J23: 1 | K23: 1 | L23: 1 | M23: 1 | N23: 1 | O23: 1 | P23: 1 | Q23: 1 | R23: 1 | S23: 1 | V23: 1 | W23: 1 | X23: 1 | AB23: 1 | AC23: 1 | AD23: 1 | AF23: 1 | AG23: 1 | AH23: 1 | AI23: 1 | AJ23: 1 | AK23: 1 | AL23: 30
A24: ERIK | B24: 1 | C24: 1 | D24: 1 | M24: 1 | X24: 1 | AF24: 1 | AI24: 1 | AL24: 7
A25: FIDELIS AMWEENYE | AK25: 1 | AL25: 1
A26: FIDELIS SKIPPER AMWEENYE EMOSHO (SKIPPER) | B26: 1 | C26: 1 | E26: 1 | F26: 1 | H26: 1 | I26: 1 | J26: 1 | M26: 1 | U26: 1 | X26: 1 | AF26: 1 | AJ26: 1 | AL26: 12
A27: FREDY BAHILI | B27: 1 | H27: 1 | K27: 1 | L27: 1 | N27: 1 | O27: 1 | Q27: 1 | R27: 1 | T27: 1 | AH27: 1 | AL27: 10
A28: GEOFFREY OYET | C28: 1 | D28: 1 | G28: 1 | I28: 1 | J28: 1 | K28: 1 | O28: 1 | P28: 1 | Q28: 1 | U28: 1 | V28: 1 | Y28: 1 | Z28: 1 | AB28: 1 | AD28: 1 | AH28: 1 | AI28: 1 | AJ28: 1 | AK28: 1 | AL28: 19
A29: GODFREY BIRUNGI | B29: 1 | C29: 1 | D29: 1 | E29: 1 | F29: 1 | G29: 1 | H29: 1 | I29: 1 | J29: 1 | K29: 1 | L29: 1 | M29: 1 | N29: 1 | O29: 1 | P29: 1 | Q29: 1 | R29: 1 | S29: 1 | T29: 1 | U29: 1 | V29: 1 | W29: 1 | X29: 1 | Y29: 1 | Z29: 1 | AA29: 1 | AB29: 1 | AC29: 1 | AD29: 1 | AE29: 1 | AF29: 1 | AG29: 1 | AH29: 1 | AI29: 1 | AJ29: 1 | AK29: 1 | AL29: 36
A30: GODFREY'S NOTETAKER | AA30: 1 | AB30: 1 | AC30: 1 | AD30: 1 | AL30: 4
A31: GOOD LORD | B31: 1 | AL31: 1
A32: HAROLD SUCCESS GOLAFALE | B32: 1 | C32: 1 | D32: 1 | E32: 1 | H32: 1 | L32: 1 | M32: 1 | N32: 1 | R32: 1 | S32: 1 | T32: 1 | W32: 1 | AF32: 1 | AK32: 1 | AL32: 14
A33: HELLEN ARIMPA | B33: 1 | D33: 1 | M33: 1 | X33: 1 | AI33: 1 | AL33: 5
A34: HENRY CHELELE | B34: 1 | C34: 1 | D34: 1 | E34: 1 | F34: 1 | G34: 1 | H34: 1 | I34: 1 | J34: 1 | L34: 1 | M34: 1 | N34: 1 | O34: 1 | P34: 1 | Q34: 1 | R34: 1 | S34: 1 | T34: 1 | W34: 1 | X34: 1 | AG34: 1 | AH34: 1 | AI34: 1 | AJ34: 1 | AK34: 1 | AL34: 25
A35: HUGUES GAKWAVU | B35: 1 | AL35: 1
A36: IBRAHIM JALLOH | AF36: 1 | AH36: 1 | AL36: 2
A37: ISAAC OGWANG | B37: 1 | C37: 1 | D37: 1 | E37: 1 | H37: 1 | I37: 1 | M37: 1 | X37: 1 | AH37: 1 | AI37: 1 | AJ37: 1 | AK37: 1 | AL37: 12
A38: ISINGOMA MAURICE | D38: 1 | E38: 1 | AL38: 2
A39: IZARUKU RONALD | B39: 1 | C39: 1 | D39: 1 | M39: 1 | X39: 1 | AF39: 1 | AH39: 1 | AJ39: 1 | AL39: 8
A40: JACQUELINE NAMYALO | B40: 1 | F40: 1 | H40: 1 | I40: 1 | J40: 1 | K40: 1 | M40: 1 | O40: 1 | X40: 1 | Z40: 1 | AF40: 1 | AG40: 1 | AH40: 1 | AI40: 1 | AL40: 14
...

Sheet RETENTION CALCULATIONS
A1: PARTICIPANTS FOR DAY 1 | B1: Column1 | C1: Column2 | D1: Column3 | E1: DAY 7 PARTICIPANTS | F1: Column4 | G1: Column5
A2: 1 | B2: ALEX MUHEREZA | C2: =COUNTA(B2:B61) -> 60 | E2: 1 | F2: ALEX MUHEREZA | G2: =COUNTA(F2:F49) -> 48
A3: 2 | B3: AMARA BAJAHA | E3: 2 | F3: ANTHONY GODSON AIDOO
A4: 3 | B4: ANTHONY GODSON AIDOO | E4: 3 | F4: AZEDRIS JAMIL KASANGO
A5: 4 | B5: ARON NTULIZE | E5: 4 | F5: BENJAMIN MALES LOKOYA
A6: 5 | B6: BENJAMIN MALES LOKOYA | E6: 5 | F6: CHANDIA FRED
A7: 6 | B7: CHERUU JUL | E7: 6 | F7: CHERUU JUL
A8: 7 | B8: CHRISTINA MOTHOBI | E8: 7 | F8: CHRISTOPHER MODI
A9: 8 | B9: CHRISTOPHER MODI | E9: 8 | F9: DANIEL ERABU
A10: 9 | B10: DANIEL ERABU | E10: 9 | F10: EL MAJID SWALEH
A11: 10 | B11: EL MAJID SWALEH | E11: 10 | F11: EMMANUEL JOBS
A12: 11 | B12: EMMANUEL JOBS | E12: 11 | F12: ERIK
A13: 12 | B13: ERIK | E13: 12 | F13: GEOFFREY OYET
A14: 13 | B14: FIDELIS SKIPPER AMWEENYE EMOSHO (SKIPPER) | E14: 13 | F14: GODFREY BIRUNGI
... A49: 48 | B49: PRINCESS MAJOLA | E49: 48 | F49: VITALIS KOECH
A50: 49 | B50: RACHEAL KYALIMPA
A51: 50 | B51: RAMATA M KEITA
A52: 51 | B52: ROBERT MAKUBUYA
A53: 52 | B53: RTN JOSES KAYUNGA
A54: 53 | B54: SABO MIKE
A55: 54 | B55: SARAH NAKAMATTE
A56: 55 | B56: SIMONPETER OUMA
A57: 56 | B57: THIS IS LINUS SANKEI
A58: 57 | B58: TORY MOLS
A59: 58 | B59: VITALIS KOECH
A60: 59 | B60: WANDA FORTUNATE
A61: 60 | B61: YUSUPHA SEESAY
B63: PARTICIPANTS DAY 16 | E63: PARTICIPANTS DAY 20
A64: 1 | B64: ALEX MUHEREZA | C64: =COUNTA(B64:B116) -> 53 | E64: AMARA BAJAHA | F64: =COUNTA(E64:E97) -> 34
A65: 2 | B65: AMARA BAJAHA | E65: ANGULA ROSAMUNDE
A66: 3 | B66: ANGULA ROSAMUNDE | E66: ANTHONY GODSON AIDOO
A67: 4 | B67: ANTHONY GODSON AIDOO | E67: CHERUU JUL
A68: 5 | B68: ARON NTULIZE | E68: CHRISTINA MOTHOBI
A69: 6 | B69: BENJAMIN MALES LOKOYA | E69: CHRISTOPHER MODI
A70: 7 | B70: CHERUU JUL | E70: CPAJULIUS CHERUIYOT
A71: 8 | B71: CHRISTINA MOTHOBI | E71: EL MAJID SWALEH
A72: 9 | B72: CHRISTOPHER MODI | E72: EMMANUEL JOBS
A73: 10 | B73: DANIEL ERABU | E73: FREDY BAHILI
A74: 11 | B74: DEUS NABIBASA | E74: GODFREY BIRUNGI
A75: 12 | B75: EL MAJID SWALEH | E75: HAROLD SUCCESS GOLAFALE
...

Sheet CHARTS

Sheet DROP OFF TABLE
A1: PARTICIPANTS NAME | B1: START SESSION | C1: END SESSIONS | E1: PARTICIPANTS NAME | F1: SUM OF START SESSION | G1: SUM OF END SESSIONS | H1: DROP OFF COLUMN
A2: AMARA BAJAHA | B2: 0 | C2: 1 | E2: ALEX MUHEREZA | F2: 2 | G2: 2 | H2: =IF(AND(F2>=6,G2<=2),1,0) -> 0 | I2: =SUM(H2:H110) -> 10
A3: ANGULA ROSAMUNDE | B3: 0 | C3: 1 | E3: AMARA BAJAHA | F3: 1 | G3: 6 | H3: =IF(AND(F3>=6,G3<=2),1,0) -> 0
A4: ANTHONY GODSON AIDOO | B4: 0 | C4: 1 | E4: ANGULA ROSAMUNDE | F4: 3 | G4: 5 | H4: =IF(AND(F4>=6,G4<=2),1,0) -> 0
A5: AZEDRIS JAMIL KASANGO | B5: 0 | C5: 1 | E5: ANTHONY GODSON AIDOO | F5: 6 | G5: 7 | H5: =IF(AND(F5>=6,G5<=2),1,0) -> 0
A6: CHERUU JUL | B6: 0 | C6: 1 | E6: ARON NTULIZE | F6: 6 | G6: 0 | H6: =IF(AND(F6>=6,G6<=2),1,0) -> 1
A7: GODFREY BIRUNGI | B7: 0 | C7: 1 | E7: AZEDRIS JAMIL KASANGO | F7: 1 | G7: 4 | H7: =IF(AND(F7>=6,G7<=2),1,0) -> 0
A8: JOHN RWARU | B8: 0 | C8: 1 | E8: BENJAMIN MALES LOKOYA | F8: 6 | G8: 4 | H8: =IF(AND(F8>=6,G8<=2),1,0) -> 0
A9: KAMAU RUTH | B9: 0 | C9: 1 | E9: BIRUNGI'S AI NOTETAKER | F9: 4 | G9: 0 | H9: =IF(AND(F9>=6,G9<=2),1,0) -> 0
A10: MARTIN LEMI | B10: 0 | C10: 1 | E10: CHANDIA FRED | F10: 4 | G10: 0 | H10: =IF(AND(F10>=6,G10<=2),1,0) -> 0
A11: MOHAMED SALLY KAMARA | B11: 0 | C11: 1 | E11: CHERUIYOT JULIUS | F11: 0 | G11: 0 | H11: =IF(AND(F11>=6,G11<=2),1,0) -> 0
A12: OCI GEOFFREY | B12: 0 | C12: 1 | E12: CHERUU JUL | F12: 6 | G12: 5 | H12: =IF(AND(F12>=6,G12<=2),1,0) -> 0
A13: YANGA SAMSON | B13: 0 | C13: 1 | E13: CHRISTINA MOTHOBI | F13: 5 | G13: 4 | H13: =IF(AND(F13>=6,G13<=2),1,0) -> 0
A14: ALEX MUHEREZA | B14: 0 | C14: 1 | E14: CHRISTOPHER MARK MODI | F14: 0 | G14: 0 | H14: =IF(AND(F14>=6,G14<=2),1,0) -> 0
... A110: RTN JOSES KAYUNGA | B110: 0 | C110: 1 | E110: Grand Total | F110: 333 | G110: 177 | H110: =IF(AND(F110>=6,G110<=2),1,0) -> 0
A111: SARAH NAKAMATTE | B111: 0 | C111: 1
A112: AMARA BAJAHA | B112: 0 | C112: 1
A113: ANGULA ROSAMUNDE | B113: 0 | C113: 1
A114: ANTHONY GODSON AIDOO | B114: 0 | C114: 1
A115: AZEDRIS JAMIL KASANGO | B115: 0 | C115: 1
A116: CHERUU JUL | B116: 0 | C116: 1
A117: CHRISTINA MOTHOBI | B117: 0 | C117: 1
A118: CHRISTOPHER MODI | B118: 0 | C118: 1
A119: CPAJULIUS CHERUIYOT | B119: 0 | C119: 1
A120: DIMA JAMES | B120: 0 | C120: 1
A121: GEOFFREY OYET | B121: 0 | C121: 1
A122: GODFREY BIRUNGI | B122: 0 | C122: 1
... A1394: YUSUPHA SEESAY | B1394: 1 | C1394: 0

Sheet ANSWERS
A1: 1 | B1: SECTION B
B2: [COUNTA(C:C)] | C2: 1394
B3: [=COUNTA(C:C)-1] | C3: 1393
A5: 2 | B5: [=ANSWERS!B2]; THE TOTAL NUMBER OF UNIQUE STUDENTS IS 108
A8: 3 | B8: OVERALL ATTENDANCE RATE=ACTUAL ATTENDANCE /TOTAL POSSIBLE ATTENDANCE
B9: =COUNTA(#REF!) -> 1
B10: =COUNTA('UNIQUE VALUES(NO DUPLICATES)'!A2:A107) -> 106
B11: TOTAL POSSIBLE RECORDS
B12: =B10*36 -> 3816
B13: =B9/B12 -> 0.00026205451
B14: OVERALL ATTENDANCE RATE WAS 35.83%
A17: 4 | B17: AVERAGE ATTENDANCE PER SESSION=ACTUAL ATTENDANCES/POSSIBLE ATTENDANCES
B18: =B9/B12 -> 0.00026205451
B19: AVERAGE ATTENDANCE PER SESSION WAS 0.35828193
A22: 5 | B22: TOTAL NUMBER OF SESSIONS=36
B23: AVERAGE HOURS=GRAND TOTAL/NUMBER OF SESSIONS
B24: =(GETPIVOTDATA("DURATION",'PIVOT TABLES'!$A$226)*24)/36 -> #REF!
B25: AVERAGE HOURS PER SESSION= 79.39533179 HOURS
A27: 6 | B27: PLANNED HOURS=NUMBER OF SESSIONS *2 HOURS PER SESSION | C27: =36*2 -> 72
B28: THE PLANNED HOURS FOR THE WHOLE SESSION WERE 72
A30: 7 | B30: ='PERFOEMANCE TABLE'!P2 -> 15
B31: 15 STUDENTS ATTENDED 80% OF THE TOTAL TRAINING TIME
A33: 8 | B33: GOTTEN FROM PIVOT TABLE | C33: FROM THE PIVOT TABLE
B34: COUNT OF DAY/36 | C34: COUNT OF DURATION
A37: 10 | B37: TOTAL HOURS ATTENDED/POSSIBLE CLASS ATTENDANCE TIME | E37: 15.31% SHOWS THE MOST COMPREHENSIVE BLENDED MEASURE
A39: 11 | B39: THE RETION RATE FOR DAY 1-7
B40: ='RETENTION CALCULATIONS'!G2/'RETENTION CALCULATIONS'!C2 -> 0.8
A42: 12 | B42: RETENTION FOR DAY16-20
B43: ='RETENTION CALCULATIONS'!F64/'RETENTION CALCULATIONS'!C64 -> 0.64150943
A45: 13 | B45: RETENTION RATE FINAL WEEK
B46: ='RETENTION CALCULATIONS'!C155/'RETENTION CALCULATIONS'!F155 -> 0.33333333
A48: 14 | B48: VOLATILITY INDEX
B49: ='VOLATILITY TABLE'!D16 -> 0.28079075
A51: 15 | B51: SESSION TO SESSION DECLINE RATE
B52: =(('RETENTION CALCULATIONS'!C2-'RETENTION CALCULATIONS'!C155)/'RETENTION CALCULATIONS'!C2)/35 -> 0.022857143
A54: 16 | B54: [=ANSWERS!A39:H147,,,THE TABLE GIVES A SUMMARY OF THOSE STUDENTS WHO QUALIFY FOR CERTIFICATION
A57: 17 | B57: [=ANSWERS!B39:I147],,THE TABLE GIVES A SUMMARY OF STUDENTS AT RISK OFFAIING DUE TO POOR PERFORMANCE
A60: 18 | B60: {=ANSWERS!E1},THE NUMBER OF STUDENTS DROP OFF = 10
A66: SECTION D
A67: 1
...

Sheet VOLATILITY TABLE
A1: TOP 10 RANK STUDENTS TABLE , AND THE AQI CHART GENERATION
A2: PARTICIPANTS NAME | C2: COUNT OF NAME
A3: GODFREY BIRUNGI | B3: 3.0720949 | C3: 36 | D3: 3.0720949 | E3: 3 | F3: 1.0240316 | G3: 1
A4: MARTIN LEMI | B4: 3.0000463 | C4: 35 | D4: 3.0000463 | E4: 3 | F4: 1.0000154 | G4: 2
A5: AMARA BAJAHA | B5: 2.9404051 | C5: 25 | D5: 2.9404051 | E5: 3 | F5: 0.98013503 | G5: 3
A6: ANTHONY GODSON AIDOO | B6: 2.9238773 | C6: 35 | D6: 2.9238773 | E6: 3 | F6: 0.97462577 | G6: 4
A7: RTN JOSES KAYUNGA | B7: 2.9219097 | C7: 34 | D7: 2.9219097 | E7: 3 | F7: 0.97396991 | G7: 5
A8: JOHN RWARU | B8: 2.8203588 | C8: 33 | D8: 2.8203588 | E8: 3 | F8: 0.9401196 | G8: 6
A9: MILDRED DRUSILA | B9: 2.7944213 | C9: 33 | D9: 2.7944213 | E9: 3 | F9: 0.93147377 | G9: 7
A10: KAMAU RUTH | B10: 2.7831597 | C10: 33 | D10: 2.7831597 | E10: 3 | F10: 0.92771991 | G10: 8
A11: JOSEPH MBOGO | B11: 2.6125579 | C11: 31 | D11: 2.6125579 | E11: 3 | F11: 0.87085262 | G11: 9
A12: EMMANUEL JOBS | B12: 2.566088 | C12: 30 | D12: 2.566088 | E12: 3 | F12: 0.85536265 | G12: 10
A14: DAYS AND PARTICIPANTS COUNT TABLE GENERATING VOLATILITY INDEX
A15: DAY NUMBER | B15: PARTICIPANTS COUNT | C15: DAILY CHANGE IN ATTENDANCE | D15: VOLATILITY INDEX
A16: 1 | B16: 60 | D16: =_xlfn.STDEV.S(C17:C51) -> 0.28079075
A17: 2 | B17: 53 | C17: =LN(B17/B16) -> -0.12405265
A18: 3 | B18: 53 | C18: =LN(B18/B17) -> 0
A19: 4 | B19: 45 | C19: =LN(B19/B18) -> -0.16362942
A20: 5 | B20: 24 | C20: =LN(B20/B19) -> -0.62860866
A21: 6 | B21: 50 | C21: =LN(B21/B20) -> 0.73396918
A22: 7 | B22: 48 | C22: =LN(B22/B21) -> -0.040821995
A23: 8 | B23: 47 | C23: =LN(B23/B22) -> -0.021053409
A24: 9 | B24: 56 | C24: =LN(B24/B23) -> 0.17520409
A25: 10 | B25: 58 | C25: =LN(B25/B24) -> 0.03509132
A26: 11 | B26: 49 | C26: =LN(B26/B25) -> -0.16862271
A27: 12 | B27: 52 | C27: =LN(B27/B26) -> 0.05942342
A28: 13 | B28: 40 | C28: =LN(B28/B27) -> -0.26236426
... A51: 36 | B51: 12 | C51: =LN(B51/B50) -> -0.81093022
